Workbook

Sheet Update
A1: Id | B1: Start time | C1: Completion time | D1: Email | E1: Name | F1: Nama Pelapor | G1: Nama Proyek | H1: Periode Progres | I1: Presentase Aktual Progress | J1: Presentase Rencana Progress | K1: Presentase BAB 1 | L1: Presentase BAB 2 | M1: Presentase BAB 3 | N1: Presentase BAB 4 | O1: Presentase BAB 5 | P1: Presentase BAB 6 | Q1: Presentase BAB 7 | R1: Presentase BAB 8 | S1: Presentase BAB 9 | T1: Presentase BAB 10 | U1: Presentase BAB 11 | V1: Presentase BAB 12 | W1: Presentase BAB 13 | X1: Presentase BAB 14 | Y1: Presentase BAB 15 | Z1: Presentase BAB 16 | AA1: Link Dokumentasi Video Drone | AB1: Link Dokumentasi Foto | AC1: Link Orthophoto | AD1: Link Reality Modeling | AE1: Periode Issue | AF1: Issue | AG1: Koordinat Proyek | AH1: Lat | AI1: Long | AJ1: Status | AK1: __PowerAppsId__
A2: 761 | B2: 44569 | C2: =B2 -> 44569 | D2: Esri_Anonymous | E2: M Saifudin Ashari | F2: =E2 -> M Saifudin Ashari | G2: Jalan Tol Bocimi Seksi 2 | H2: 44591 | I2: 76.851 | J2: 78.251 | K2: 0.915 | L2: 0.865 | M2: 0.864 | N2: 0.885 | O2: 0.423 | P2: 0.516 | Q2: 0.54 | R2: 0.44 | S2: 0.889 | T2: 0.019 | U2: 0.513 | V2: 0 | W2: 0 | X2: 0.31 | Y2: 0 | AG2: =VLOOKUP(OfficeForms.Table[[#This Row],[Nama Proyek]],'Nama Proyek'!$D$2:$G$29,4,0) -> -6.80675464,106.785366 | AK2: 01295f48-974d-48b4-b138-23608606326d
A3: 762 | B3: 44569 | C3: =B3 -> 44569 | D3: Esri_Anonymous | E3: M Saifudin Ashari | F3: =E3 -> M Saifudin Ashari | G3: Jalan Tol Bocimi Seksi 2 | H3: 44619 | I3: 77.925 | J3: 81.748 | K3: 0.915 | L3: 0.865 | M3: 0.872 | N3: 0.885 | O3: 0.428 | P3: 0.518 | Q3: 0.54 | R3: 0.461 | S3: 0.901 | T3: 0.019 | U3: 0.516 | V3: 0 | W3: 0 | X3: 0.31 | Y3: 0 | AG3: =VLOOKUP(OfficeForms.Table[[#This Row],[Nama Proyek]],'Nama Proyek'!$D$2:$G$29,4,0) -> -6.80675464,106.785366 | AK3: 08fb3e28-02c7-48ac-a421-4bed199374e4
A4: 763 | B4: 44569 | C4: =B4 -> 44569 | D4: Esri_Anonymous | E4: M Saifudin Ashari | F4: =E4 -> M Saifudin Ashari | G4: Jalan Tol Bocimi Seksi 2 | H4: 44647 | I4: 79.017 | J4: 87.502 | K4: 0.915 | L4: 0.865 | M4: 0.883 | N4: 0.885 | O4: 0.439 | P4: 0.518 | Q4: 0.54 | R4: 0.475 | S4: 0.905 | T4: 0.233 | U4: 0.525 | V4: 0 | W4: 0 | X4: 0.31 | Y4: 0 | AG4: =VLOOKUP(OfficeForms.Table[[#This Row],[Nama Proyek]],'Nama Proyek'!$D$2:$G$29,4,0) -> -6.80675464,106.785366 | AK4: 500ce746-deba-47b9-9ae4-7498cd048bba
A5: 813 | B5: 44569 | C5: =B5 -> 44569 | D5: Esri_Anonymous | E5: M Saifudin Ashari | F5: =E5 -> M Saifudin Ashari | G5: Jalan Tol Bocimi Seksi 2 | H5: 44675 | I5: 79.052 | J5: 79.208 | K5: 0.901 | L5: 0.987 | M5: 0.891 | N5: 0.874 | O5: 0.445 | P5: 0.519 | Q5: 0.54 | R5: 0.485 | S5: 0.892 | T5: 0.451 | U5: 0.536 | V5: 0 | W5: 0 | X5: 0.305 | Y5: 0 | AG5: =VLOOKUP(OfficeForms.Table[[#This Row],[Nama Proyek]],'Nama Proyek'!$D$2:$G$29,4,0) -> -6.80675464,106.785366 | AK5: 1205050c-ff5d-4ff0-9aa0-81d8fbcf4f08
A6: 814 | B6: 44569 | C6: =B6 -> 44569 | D6: Esri_Anonymous | E6: M Saifudin Ashari | F6: =E6 -> M Saifudin Ashari | G6: Jalan Tol Bocimi Seksi 2 | H6: 44710 | I6: 79.502 | J6: 82.926 | K6: 0.901 | L6: 0.987 | M6: 0.901 | N6: 0.874 | O6: 0.457 | P6: 0.538 | Q6: 0.544 | R6: 0.487 | S6: 0.892 | T6: 0.451 | U6: 0.543 | V6: 0 | W6: 0 | X6: 0.305 | Y6: 0 | AG6: =VLOOKUP(OfficeForms.Table[[#This Row],[Nama Proyek]],'Nama Proyek'!$D$2:$G$29,4,0) -> -6.80675464,106.785366 | AK6: c68e95c8-1f3f-4599-8951-5f49ec41862c
A7: 815 | B7: 44569 | C7: =B7 -> 44569 | D7: Esri_Anonymous | E7: M Saifudin Ashari | F7: =E7 -> M Saifudin Ashari | G7: Jalan Tol Bocimi Seksi 2 | H7: 44735 | I7: 80.824 | J7: 87.407 | K7: 0.901 | L7: 0.987 | M7: 0.918 | N7: 0.874 | O7: 0.467 | P7: 0.547 | Q7: 0.558 | R7: 0.501 | S7: 0.907 | T7: 0.497 | U7: 0.557 | V7: 0 | W7: 0 | X7: 0.305 | Y7: 0 | AG7: =VLOOKUP(OfficeForms.Table[[#This Row],[Nama Proyek]],'Nama Proyek'!$D$2:$G$29,4,0) -> -6.80675464,106.785366 | AK7: e1421f62-7e4c-428e-b28a-90197d1bff3a
A8: 236 | B8: 44569 | C8: =B8 -> 44569 | D8: andi.firdaus_waskitakarya | E8: Basuki Rahmat Hakim | F8: Basuki Rahmat Hakim | G8: Jalan Long Semamu - Long Bawan 2 (JOP 70%) | H8: 44763 | I8: 28.886 | J8: 30.71 | K8: 0 | L8: 27.379 | M8: 0 | N8: 0 | O8: 0 | P8: 0 | Q8: 0 | R8: 0.231 | S8: 0 | T8: 0 | U8: 0 | V8: 0 | W8: 0 | X8: 0 | Y8: 0 | AG8: =VLOOKUP(OfficeForms.Table[[#This Row],[Nama Proyek]],'Nama Proyek'!$D$2:$G$29,4,0) -> 3.76047575,115.89977678 | AK8: 655347d4-a916-4a70-bd8c-c68781c0163f
A9: 243 | B9: 44569 | C9: =B9 -> 44569 | D9: Esri_Anonymous | E9: Basuki Rahmat Hakim | F9: =E9 -> Basuki Rahmat Hakim | G9: Jalan Long Semamu - Long Bawan 2 (JOP 70%) | H9: 44763 | I9: 28.886 | J9: 30.71 | K9: 0 | L9: 27.379 | M9: 0 | N9: 0 | O9: 0 | P9: 0 | Q9: 0 | R9: 0.231 | S9: 0 | T9: 0 | U9: 0 | V9: 0 | W9: 0 | X9: 0 | Y9: 0 | AG9: =VLOOKUP(OfficeForms.Table[[#This Row],[Nama Proyek]],'Nama Proyek'!$D$2:$G$29,4,0) -> 3.76047575,115.89977678 | AK9: 0fbc4e87-ee39-4edb-8909-ced495f1002e
A10: 180 | B10: 44569 | C10: =B10 -> 44569 | D10: Esri_Anonymous | E10: Riezky Ibnu Prasetyo | F10: =E10 -> Riezky Ibnu Prasetyo | G10: Jalan Tol Cibitung - Cilincing Seksi 2 | H10: 44766 | I10: 83.915 | J10: 0 | K10: 0 | L10: 0 | M10: 0 | N10: 0.003 | O10: 0 | P10: 0 | Q10: 0 | R10: 0.024 | S10: 2.811 | T10: 0 | U10: 0 | V10: 0 | W10: 0 | X10: 0 | Y10: 0 | AG10: =VLOOKUP(OfficeForms.Table[[#This Row],[Nama Proyek]],'Nama Proyek'!$D$2:$G$29,4,0) -> -6.13491053,106.93675986 | AK10: c6a5273c-ee19-49b2-81e0-8e030882b53c
A11: 166 | B11: 44569 | C11: =B11 -> 44569 | D11: Esri_Anonymous | E11: Haryo Widiandoko | F11: =E11 -> Haryo Widiandoko | G11: Jalan Tol Japek II Selatan Paket 3 | H11: 44771 | I11: 75.869 | J11: 79.785 | K11: 27.49 | L11: 76.97 | M11: 73.02 | N11: 77.83 | O11: 39.17 | P11: 68.16 | Q11: 71.86 | R11: 66 | S11: 97.88 | T11: 0 | U11: 23.83 | V11: 6.3 | W11: 0 | X11: 78.49 | Y11: 0 | AG11: =VLOOKUP(OfficeForms.Table[[#This Row],[Nama Proyek]],'Nama Proyek'!$D$2:$G$29,4,0) -> -6.42873464,107.19897003 | AK11: 19d374c5-f708-4999-bf5b-03c18c3f703c
A12: 82 | B12: 44569 | C12: =B12 -> 44569 | D12: Esri_Anonymous | E12: Alfian Budi Prasetya | F12: =E12 -> Alfian Budi Prasetya | G12: Jalan Akses dan Kawasan Avasta | H12: 44773 | I12: 21.582 | J12: 94.148 | K12: 17.804 | L12: 1.322 | M12: 0.287 | N12: 0.249 | O12: 0 | P12: 0 | Q12: 0 | R12: 0 | S12: 0 | T12: 0 | U12: 0 | V12: 0 | W12: 0 | X12: 0 | Y12: 0 | AF12: Buangan Galian Boundary Drain | AG12: =VLOOKUP(OfficeForms.Table[[#This Row],[Nama Proyek]],'Nama Proyek'!$D$2:$G$29,4,0) -> -6.12967558,107.07321308 | AK12: 3c7732a5-9cc7-4aaf-b3c2-ffbe6b8be0d3
A13: 865 | B13: 44569 | C13: =B13 -> 44569 | D13: Esri_Anonymous | E13: M Saifudin Ashari | F13: =E13 -> M Saifudin Ashari | G13: Jalan Tol Bocimi Seksi 2 | H13: 44773 | I13: 83.896 | J13: 92.387 | K13: 0.901 | L13: 0.987 | M13: 0.927 | N13: 0.877 | O13: 0.481 | P13: 0.603 | Q13: 0.629 | R13: 0.536 | S13: 0.939 | T13: 0.769 | U13: 0.567 | V13: 0 | W13: 0 | X13: 0.305 | Y13: 0 | AG13: =VLOOKUP(OfficeForms.Table[[#This Row],[Nama Proyek]],'Nama Proyek'!$D$2:$G$29,4,0) -> -6.80675464,106.785366 | AK13: 16d4afbe-7b98-48a8-98ae-c62a16e8e0b8
A14: 83 | B14: 44569 | C14: =B14 -> 44569 | D14: Esri_Anonymous | E14: Alfian Budi Prasetya | F14: =E14 -> Alfian Budi Prasetya | G14: Jalan Akses dan Kawasan Avasta | I14: 0 | J14: 0 | K14: 0 | L14: 0 | M14: 0 | N14: 0 | O14: 0 | P14: 0 | Q14: 0 | R14: 0 | S14: 0 | T14: 0 | U14: 0 | V14: 0 | W14: 0 | X14: 0 | Y14: 0 | AE14: 29/07/22 | AG14: =VLOOKUP(OfficeForms.Table[[#This Row],[Nama Proyek]],'Nama Proyek'!$D$2:$G$29,4,0) -> -6.12967558,107.07321308 | AK14: c197a9bb-6395-4e63-a980-725996468e2f
A15: 186 | B15: 44569 | C15: =B15 -> 44569 | D15: Esri_Anonymous | E15: Nizar Zulkarnain | F15: =E15 -> Nizar Zulkarnain | G15: Jalan Tol Cimanggis Cibitung Seksi 2 | I15: 0 | J15: 0 | K15: 0 | L15: 0 | M15: 0 | N15: 0 | O15: 0 | P15: 0 | Q15: 0 | R15: 0 | S15: 0 | T15: 0 | U15: 0 | V15: 0 | W15: 0 | X15: 0 | Y15: 0 | AC15: https://ptwaskita-my.sharepoint.com/:i:/g/personal/nizar_zulkarnain_waskita_co_id/EaUVyfC89PVBr9PeS1_jnhgB8f_-NXtHOoYDIYkFKtM6yg?e=aVNgqT | AF15: Steel Box Girder Elevated Transyogi masih belum dikirim seluruhnya secara kontinu oleh BMI. Persiapan erection masih terkendala alat support erection masih belum disetting untuk erection. | AG15: =VLOOKUP(OfficeForms.Table[[#This Row],[Nama Proyek]],'Nama Proyek'!$D$2:$G$29,4,0) -> -6.35008011,107.02324233 | AK15: 8641390f-d4d3-416d-b55e-344112a1a6f8
A16: 251 | B16: 44569 | C16: =B16 -> 44569 | D16: Esri_Anonymous | E16: Riezky Ibnu Prasetyo | F16: =E16 -> Riezky Ibnu Prasetyo | G16: Jalan Tol Cibitung - Cilincing Seksi 2 | I16: 0 | J16: 0 | K16: 0 | L16: 0 | M16: 0 | N16: 0 | O16: 0 | P16: 0 | Q16: 0 | R16: 0 | S16: 0 | T16: 0 | U16: 0 | V16: 0 | W16: 0 | X16: 0 | Y16: 0 | AA16: https://drive.google.com/drive/u/2/folders/1TPNPPyr5KG-BOau-0_zVewD5BD4OGclD | AB16: https://drive.google.com/drive/u/2/folders/1TPNPPyr5KG-BOau-0_zVewD5BD4OGclD | AC16: https://ptwaskita-my.sharepoint.com/:f:/g/personal/fahmi_waskita_co_id/EmNyIicQoohIvNQFWujff_kB_kDxEQuFgLeC7aB4Z_3QSA?e=2BxylI | AD16: https://ptwaskita-my.sharepoint.com/:f:/g/personal/fahmi_waskita_co_id/EmNyIicQoohIvNQFWujff_kB_kDxEQuFgLeC7aB4Z_3QSA?e=2BxylI | AG16: =VLOOKUP(OfficeForms.Table[[#This Row],[Nama Proyek]],'Nama Proyek'!$D$2:$G$29,4,0) -> -6.13491053,106.93675986 | AK16: d94abc25-bcdd-4d2c-bf59-d0b8f0c91a69
A17: 252 | B17: 44569 | C17: =B17 -> 44569 | D17: Esri_Anonymous | E17: Riezky Ibnu Prasetyo | F17: =E17 -> Riezky Ibnu Prasetyo | G17: Jalan Tol Cibitung - Cilincing Seksi 2 | I17: 0 | J17: 0 | K17: 0 | L17: 0 | M17: 0 | N17: 0 | O17: 0 | P17: 0 | Q17: 0 | R17: 0 | S17: 0 | T17: 0 | U17: 0 | V17: 0 | W17: 0 | X17: 0 | Y17: 0 | AA17: https://drive.google.com/file/d/15Jh9CL6Dd-vDUCFdby6THO7TZ1Tx8len/view?usp=sharing | AG17: =VLOOKUP(OfficeForms.Table[[#This Row],[Nama Proyek]],'Nama Proyek'!$D$2:$G$29,4,0) -> -6.13491053,106.93675986 | AK17: 71f31616-6be4-4207-b82d-9b4732f76118
A18: 207 | B18: 44573 | C18: =B18 -> 44573 | D18: Esri_Anonymous | E18: Haryo Widiandoko | F18: =E18 -> Haryo Widiandoko | G18: Jalan Tol Japek II Selatan Paket 3 | H18: 44893 | I18: 69.837 | J18: 71.156 | K18: 0.112 | L18: 0.128 | M18: 20.685 | N18: 2.035 | O18: 2.355 | P18: 0.052 | Q18: 0.585 | R18: 10.308 | S18: 30.691 | T18: 0.612 | U18: 1.297 | V18: 0.031 | W18: 0 | X18: 0.739 | Y18: 0 | AG18: =VLOOKUP(OfficeForms.Table[[#This Row],[Nama Proyek]],'Nama Proyek'!$D$2:$G$29,4,0) -> -6.42873464,107.19897003 | AK18: 853cb85b-63bb-4a20-8e0b-adf4d84ac83f
A19: 642 | B19: 44573 | C19: =B19 -> 44573 | D19: Esri_Anonymous | E19: Banyu Purwita | F19: =E19 -> Banyu Purwita | G19: Fly Over Simpang Sekip - Palembang (JOI 65%) | I19: 0 | J19: 0 | K19: 0 | L19: 0 | M19: 0 | N19: 0 | O19: 0 | P19: 0 | Q19: 0 | R19: 0 | S19: 0 | T19: 0 | U19: 0 | V19: 0 | W19: 0 | X19: 0 | Y19: 0 | AA19: https://ptwaskita-my.sharepoint.com/:f:/g/personal/banyu_purwita_waskita_co_id/EqTjUHNq3YxAussMGuMB4SsB4kHg8l1RoWIAsL3jYUQ9ig?e=wkoXee | AB19: https://ptwaskita-my.sharepoint.com/:f:/g/personal/banyu_purwita_waskita_co_id/EqTjUHNq3YxAussMGuMB4SsB4kHg8l1RoWIAsL3jYUQ9ig?e=wkoXee | AC19: https://ptwaskita-my.sharepoint.com/:f:/g/personal/banyu_purwita_waskita_co_id/EqTjUHNq3YxAussMGuMB4SsB4kHg8l1RoWIAsL3jYUQ9ig?e=wkoXee | AD19: https://ptwaskita-my.sharepoint.com/:f:/g/personal/banyu_purwita_waskita_co_id/EqTjUHNq3YxAussMGuMB4SsB4kHg8l1RoWIAsL3jYUQ9ig?e=wkoXee | AG19: =VLOOKUP(OfficeForms.Table[[#This Row],[Nama Proyek]],'Nama Proyek'!$D$2:$G$29,4,0) -> -2.95293103,104.75455094 | AK19: 89b87f51-6f64-40d2-b72a-c60f36713864
A20: 253 | B20: 44600 | C20: =B20 -> 44600 | D20: Esri_Anonymous | E20: Fajar Sodiq Febriansyah | F20: =E20 -> Fajar Sodiq Febriansyah | G20: Jalan Tol Paspro Seksi 4 | H20: 44735 | I20: 27.1694 | J20: 55.7068 | K20: 0.161 | L20: 0.0804 | M20: 13.0715 | N20: 0.2864 | O20: 0.0446 | P20: 0.0053 | Q20: 0.0006 | R20: 0.3957 | S20: 15.6692 | T20: 0 | U20: 0.0819 | V20: 0 | W20: 0 | X20: 0.1042 | Y20: 0 | AG20: =VLOOKUP(OfficeForms.Table[[#This Row],[Nama Proyek]],'Nama Proyek'!$D$2:$G$29,4,0) -> -7.82225167,113.29968319 | AK20: 79671d44-4c09-4490-b3d4-56864afc245b
A21: 254 | B21: 44600 | C21: =B21 -> 44600 | D21: Esri_Anonymous | E21: Ajik Prastiyo | F21: =E21 -> Ajik Prastiyo | G21: Jalan Tol Paspro Seksi 4 | H21: 44773 | I21: 44.002827 | J21: 48.305322 | K21: 0.29875857 | L21: 0.09688374 | M21: 20.333593 | N21: 0.4063855 | O21: 0.09679439 | P21: 0.01773914 | Q21: 0.00071883 | R21: 0.86200131 | S21: 21.364516 | T21: 0 | U21: 0.1002754 | V21: 0 | W21: 0.03659606 | X21: 0.12110213 | Y21: 0 | AF21: Pekerjaan Beton Struktur Jumlah BP sudah terpenuhi, flow material (pasir, semen, split) belum terpenuhi | AG21: =VLOOKUP(OfficeForms.Table[[#This Row],[Nama Proyek]],'Nama Proyek'!$D$2:$G$29,4,0) -> -7.82225167,113.29968319 | AK21: 3769f100-aa01-4ba6-b8a3-c10358e5be4e
A22: 259 | B22: 44600 | C22: =B22 -> 44600 | D22: Esri_Anonymous | E22: Nungki Herdiana | F22: =E22 -> Nungki Herdiana | G22: Proyek Peningkatan Jalan Sp. Siligita - Kempinski | H22: 44775 | I22: 66.31 | J22: 66.34 | K22: 78.29 | L22: 98.07 | M22: 94.31 | N22: 7.66 | O22: 52.04 | P22: 184.85 | Q22: 59.98 | R22: 0 | S22: 0 | T22: 0 | U22: 0 | V22: 0 | W22: 0 | X22: 0 | Y22: 0 | AF22: Progress pekerjaan item Cipta Karya 10.09 % belum dapat ditagihkan terkait dengan HPS item baru dan spesifikasi teknis untuk dasar pembayaran. | AG22: =VLOOKUP(OfficeForms.Table[[#This Row],[Nama Proyek]],'Nama Proyek'!$D$2:$G$29,4,0) -> #N/A | AK22: 8ec8e0fd-939e-45bd-b4c4-3dba6514f144
A23: 255 | B23: 44600 | C23: =B23 -> 44600 | D23: Esri_Anonymous | E23: Ajik Prastiyo | F23: =E23 -> Ajik Prastiyo | G23: Jalan Tol Paspro Seksi 4 | I23: 0 | J23: 0 | K23: 0 | L23: 0 | M23: 0 | N23: 0 | O23: 0 | P23: 0 | Q23: 0 | R23: 0 | S23: 0 | T23: 0 | U23: 0 | V23: 0 | W23: 0 | X23: 0 | Y23: 0 | AE23: 44569 | AF23: Kekurangan fleet untuk melakukan pekerjaan tanah sesuai target | AG23: =VLOOKUP(OfficeForms.Table[[#This Row],[Nama Proyek]],'Nama Proyek'!$D$2:$G$29,4,0) -> -7.82225167,113.29968319 | AK23: 0d0edcf6-4a51-4c67-895d-a686a6e81e92
A24: 256 | B24: 44600 | C24: =B24 -> 44600 | D24: Esri_Anonymous | E24: Ajik Prastiyo | F24: =E24 -> Ajik Prastiyo | G24: Jalan Tol Paspro Seksi 4 | I24: 0 | J24: 0 | K24: 0 | L24: 0 | M24: 0 | N24: 0 | O24: 0 | P24: 0 | Q24: 0 | R24: 0 | S24: 0 | T24: 0 | U24: 0 | V24: 0 | W24: 0 | X24: 0 | Y24: 0 | AE24: 44569 | AF24: Adanya beberapa lahan konsinyasi yang belum bebas dengan nilai UGK sebesar 10,83 M, pada lokasi IC STA 03+150 – 03+500, yang mengganggu mobilisasi pekerjaan. | AG24: =VLOOKUP(OfficeForms.Table[[#This Row],[Nama Proyek]],'Nama Proyek'!$D$2:$G$29,4,0) -> -7.82225167,113.29968319 | AK24: fe9b9e08-32ae-4cf2-8e70-64a9d38d0277
A25: 257 | B25: 44600 | C25: =B25 -> 44600 | D25: Esri_Anonymous | E25: Ajik Prastiyo | F25: =E25 -> Ajik Prastiyo | G25: Jalan Tol Paspro Seksi 4 | I25: 0 | J25: 0 | K25: 0 | L25: 0 | M25: 0 | N25: 0 | O25: 0 | P25: 0 | Q25: 0 | R25: 0 | S25: 0 | T25: 0 | U25: 0 | V25: 0 | W25: 0 | X25: 0 | Y25: 0 | AE25: 31/07/22 | AG25: =VLOOKUP(OfficeForms.Table[[#This Row],[Nama Proyek]],'Nama Proyek'!$D$2:$G$29,4,0) -> -7.82225167,113.29968319 | AK25: 96664f5d-0d79-4fe6-a9b9-50bd634f2668
A26: 260 | B26: 44600 | C26: =B26 -> 44600 | D26: Esri_Anonymous | E26: Nungki Herdiana | F26: =E26 -> Nungki Herdiana | G26: Proyek Peningkatan Jalan Sp. Siligita - Kempinski | I26: 0 | J26: 0 | K26: 0 | L26: 0 | M26: 0 | N26: 0 | O26: 0 | P26: 0 | Q26: 0 | R26: 0 | S26: 0 | T26: 0 | U26: 0 | V26: 0 | W26: 0 | X26: 0 | Y26: 0 | AE26: 44600 | AF26: Addendum final menunggu addendum item ke Cipta Karya | AG26: =VLOOKUP(OfficeForms.Table[[#This Row],[Nama Proyek]],'Nama Proyek'!$D$2:$G$29,4,0) -> #N/A | AK26: 2aa8c67d-d1fd-4c23-bbf9-7476588f45b4
A27: 261 | B27: 44600 | C27: =B27 -> 44600 | D27: Esri_Anonymous | E27: Nungki Herdiana | F27: =E27 -> Nungki Herdiana | G27: Proyek Peningkatan Jalan Sp. Siligita - Kempinski | I27: 0 | J27: 0 | K27: 0 | L27: 0 | M27: 0 | N27: 0 | O27: 0 | P27: 0 | Q27: 0 | R27: 0 | S27: 0 | T27: 0 | U27: 0 | V27: 0 | W27: 0 | X27: 0 | Y27: 0 | AE27: 44600 | AF27: Keterlambatan pengiriman material Ducting dikarenakan WPB tidak memiliki kemampuann finansial untuk membayar expedisi. | AG27: =VLOOKUP(OfficeForms.Table[[#This Row],[Nama Proyek]],'Nama Proyek'!$D$2:$G$29,4,0) -> #N/A | AK27: 6166c7e5-06d4-40c4-9da5-7e6822445089
A28: 262 | B28: 44600 | C28: =B28 -> 44600 | D28: Esri_Anonymous | E28: Nungki Herdiana | F28: =E28 -> Nungki Herdiana | G28: Proyek Peningkatan Jalan Sp. Siligita - Kempinski | I28: 0 | J28: 0 | K28: 0 | L28: 0 | M28: 0 | N28: 0 | O28: 0 | P28: 0 | Q28: 0 | R28: 0 | S28: 0 | T28: 0 | U28: 0 | V28: 0 | W28: 0 | X28: 0 | Y28: 0 | AE28: 44600 | AF28: Pada area Jalan Siligita - Kempinski sering dilakukan event, baik dari pihak instansi maupun kegiatan kenegaraan sehingga Polisi menghentikan aktifitas proyek saat tamu menuju lokasi. | AG28: =VLOOKUP(OfficeForms.Table[[#This Row],[Nama Proyek]],'Nama Proyek'!$D$2:$G$29,4,0) -> #N/A | AK28: 34bee91d-8648-42ab-87bc-94cad0314020
A29: 263 | B29: 44600 | C29: =B29 -> 44600 | D29: Esri_Anonymous | E29: Nungki Herdiana | F29: =E29 -> Nungki Herdiana | G29: Proyek Peningkatan Jalan Sp. Siligita - Kempinski | I29: 0 | J29: 0 | K29: 0 | L29: 0 | M29: 0 | N29: 0 | O29: 0 | P29: 0 | Q29: 0 | R29: 0 | S29: 0 | T29: 0 | U29: 0 | V29: 0 | W29: 0 | X29: 0 | Y29: 0 | AE29: 44600 | AF29: Pekerjan Pengaspalan mengalami keterlambatan dikarenakan subkon pekerjaan aspal tidak memiliki kemampuan finansial yang baik | AG29: =VLOOKUP(OfficeForms.Table[[#This Row],[Nama Proyek]],'Nama Proyek'!$D$2:$G$29,4,0) -> #N/A | AK29: ee12e7a8-ab13-42e3-babb-8b31431e7c1c
A30: 264 | B30: 44600 | C30: =B30 -> 44600 | D30: Esri_Anonymous | E30: Nungki Herdiana | F30: =E30 -> Nungki Herdiana | G30: Proyek Peningkatan Jalan Sp. Siligita - Kempinski | I30: 0 | J30: 0 | K30: 0 | L30: 0 | M30: 0 | N30: 0 | O30: 0 | P30: 0 | Q30: 0 | R30: 0 | S30: 0 | T30: 0 | U30: 0 | V30: 0 | W30: 0 | X30: 0 | Y30: 0 | AE30: 44600 | AG30: =VLOOKUP(OfficeForms.Table[[#This Row],[Nama Proyek]],'Nama Proyek'!$D$2:$G$29,4,0) -> #N/A | AK30: ee7a42ce-6524-429f-858e-4f27d20b88d0
A31: 477 | B31: 44600 | C31: =B31 -> 44600 | D31: Esri_Anonymous | E31: Haryo Widiandoko | F31: =E31 -> Haryo Widiandoko | G31: Jalan Tol Japek II Selatan Paket 3 | I31: 0 | J31: 0 | K31: 0 | L31: 0 | M31: 0 | N31: 0 | O31: 0 | P31: 0 | Q31: 0 | R31: 0 | S31: 0 | T31: 0 | U31: 0 | V31: 0 | W31: 0 | X31: 0 | Y31: 0 | AA31: https://drive.google.com/file/d/1_m11qHP04rEw3MA-Ex-QOBusDt3_tSDo/view?usp=sharing | AB31: https://drive.google.com/file/d/1AhBYaMU89WHRri0kBpF5ucBZBmfRVGba/view?usp=sharing | AC31: https://ptwaskita-my.sharepoint.com/:f:/r/personal/fahmi_waskita_co_id/Documents/BIM%20-%20INFRA%202/Project/WKINF2%20-%20D32C19006%20(Jakarta%20-%20Cikampek%20II%20Selatan%20Paket%203)/3.%20PUBLISHED/9.%20REALITY%20MODELING/202207%20-%20Juli%202022/SS%2 | AD31: https://ptwaskita-my.sharepoint.com/:f:/r/personal/fahmi_waskita_co_id/Documents/BIM%20-%20INFRA%202/Project/WKINF2%20-%20D32C19006%20(Jakarta%20-%20Cikampek%20II%20Selatan%20Paket%203)/3.%20PUBLISHED/9.%20REALITY%20MODELING/202207%20-%20Juli%202022?csf= | AG31: =VLOOKUP(OfficeForms.Table[[#This Row],[Nama Proyek]],'Nama Proyek'!$D$2:$G$29,4,0) -> -6.42873464,107.19897003 | AK31: 2e8eaf7c-f39d-4660-b564-95301d839974
A32: 867 | B32: 44603 | C32: =B32 -> 44603 | D32: Esri_Anonymous | E32: Muhamad Saifudin Ashari | F32: =E32 -> Muhamad Saifudin Ashari | G32: Jalan Tol Bocimi Seksi 2 | H32: 44834 | I32: 87.597 | J32: 89.257 | K32: 0.985 | L32: 0.878 | M32: 0.959 | N32: 0.982 | O32: 0.629 | P32: 0.818 | Q32: 0.822 | R32: 0.677 | S32: 0.946 | T32: 0.826 | U32: 0.51 | V32: 0 | W32: 0 | X32: 0.32 | Y32: 0 | AG32: =VLOOKUP(OfficeForms.Table[[#This Row],[Nama Proyek]],'Nama Proyek'!$D$2:$G$29,4,0) -> -6.80675464,106.785366 | AK32: 0e9bf1c8-34fd-4480-ae73-d21fc719798f
A33: 367 | B33: 44603 | C33: =B33 -> 44603 | D33: Esri_Anonymous | E33: Nungki Herdiana | F33: =E33 -> Nungki Herdiana | G33: Proyek Peningkatan Jalan Sp. Siligita - Kempinski | H33: 44854 | I33: 100 | J33: 100 | K33: 100 | L33: 100 | M33: 100 | N33: 100 | O33: 100 | P33: 100 | Q33: 100 | R33: 0 | S33: 100 | T33: 0 | U33: 0 | V33: 0 | W33: 0 | X33: 0 | Y33: 0 | AF33: Keterlambatan terbitnya Jaminan Pemeliharaan dikarenakan belum disahkan ADD 3 oleh para pihak | AG33: =VLOOKUP(OfficeForms.Table[[#This Row],[Nama Proyek]],'Nama Proyek'!$D$2:$G$29,4,0) -> #N/A | AK33: a3ae426c-b68b-430c-94bc-0144fcf21e0d
A34: 203 | B34: 44603 | C34: =B34 -> 44603 | D34: Esri_Anonymous | E34: Haryo Widiandoko | F34: =E34 -> Haryo Widiandoko | G34: Jalan Tol Japek II Selatan Paket 3 | H34: 44862 | I34: 84.578 | J34: 85.969 | K34: 27.49 | L34: 76.97 | M34: 84.51 | N34: 87.07 | O34: 43.52 | P34: 68.16 | Q34: 83.55 | R34: 81.3 | S34: 103.41 | T34: 0 | U34: 31.76 | V34: 6.3 | W34: 0 | X34: 78.49 | Y34: 0 | AG34: =VLOOKUP(OfficeForms.Table[[#This Row],[Nama Proyek]],'Nama Proyek'!$D$2:$G$29,4,0) -> -6.42873464,107.19897003 | AK34: 0e050198-432c-4fe3-a1a6-964ecb201086
A35: 248 | B35: 44603 | C35: =B35 -> 44603 | D35: Esri_Anonymous | E35: Muhamad Saifudin Ashari | F35: Muhamad Saifudin Ashari | G35: Jalan Tol Bocimi Seksi 2 | I35: 0 | J35: 0 | K35: 0 | L35: 0 | M35: 0 | N35: 0 | O35: 0 | P35: 0 | Q35: 0 | R35: 0 | S35: 0 | T35: 0 | U35: 0 | V35: 0 | W35: 0 | X35: 0 | Y35: 0 | AE35: 17/10/22 | AF35: Semua girder (PCI & Steel Box Girder) JU Akses Cibadak telah selesai tererection | AG35: =VLOOKUP(OfficeForms.Table[[#This Row],[Nama Proyek]],'Nama Proyek'!$D$2:$G$29,4,0) -> -6.80675464,106.785366 | AK35: 1d11f478-5f50-4682-b3cb-160711d6a1f6
A36: 368 | B36: 44603 | C36: =B36 -> 44603 | D36: Esri_Anonymous | E36: Nungki Herdiana | F36: =E36 -> Nungki Herdiana | G36: Proyek Peningkatan Jalan Sp. Siligita - Kempinski | I36: 0 | J36: 0 | K36: 0 | L36: 0 | M36: 0 | N36: 0 | O36: 0 | P36: 0 | Q36: 0 | R36: 0 | S36: 0 | T36: 0 | U36: 0 | V36: 0 | W36: 0 | X36: 0 | Y36: 0 | AE36: 20/10/22 | AF36: Adanya genangan air di Sta. 4+100 jalan siligita-Kempinski (depan hotel vouk) dikarenakan elevasi badan jalan rencana di bawah elevasi tanah warga yang tidak mau dibebaskan dan curah hujan yang tinggi. | AG36: =VLOOKUP(OfficeForms.Table[[#This Row],[Nama Proyek]],'Nama Proyek'!$D$2:$G$29,4,0) -> #N/A | AK36: 58899984-e84f-4c92-aeb2-b82a58c8b1c7
A37: 369 | B37: 44603 | C37: =B37 -> 44603 | D37: Esri_Anonymous | E37: Nungki Herdiana | F37: =E37 -> Nungki Herdiana | G37: Proyek Peningkatan Jalan Sp. Siligita - Kempinski | I37: 0 | J37: 0 | K37: 0 | L37: 0 | M37: 0 | N37: 0 | O37: 0 | P37: 0 | Q37: 0 | R37: 0 | S37: 0 | T37: 0 | U37: 0 | V37: 0 | W37: 0 | X37: 0 | Y37: 0 | AE37: 20/10/22 | AF37: Fungsional Nataru Bocimi Seksi 2 dilaksanakan pada 23 sd 31 Des 2022 dan arus balik Nataru pada 1 sd 2 Jan 2023 | AG37: =VLOOKUP(OfficeForms.Table[[#This Row],[Nama Proyek]],'Nama Proyek'!$D$2:$G$29,4,0) -> #N/A | AK37: f646259a-2611-4fce-8fdb-e901a4a2fb47
A38: 371 | B38: 44603 | C38: =B38 -> 44603 | D38: Esri_Anonymous | E38: YECKASTORO JANUWISESA | F38: =E38 -> YECKASTORO JANUWISESA | G38: Proyek Peningkatan Jalan Sp. Siligita - Kempinski | I38: 0 | J38: 0 | K38: 0 | L38: 0 | M38: 0 | N38: 0 | O38: 0 | P38: 0 | Q38: 0 | R38: 0 | S38: 0 | T38: 0 | U38: 0 | V38: 0 | W38: 0 | X38: 0 | Y38: 0 | AA38: https://drive.google.com/file/d/1cRh0mkRmYQapfKQc5MJNXwwddD5qArPv/view?usp=share_link | AE38: =[1]!OfficeForms.Table[[#This Row],[Waktu selesai]] -> #REF! | AF38: Bocimi Seksi 2 dibuka sebagai jalur fungsional Libur Natal 2022 dan tahun baru 2023 pada 23 Desember sd 2 Januari 2023 | AG38: =VLOOKUP(OfficeForms.Table[[#This Row],[Nama Proyek]],'Nama Proyek'!$D$2:$G$29,4,0) -> #N/A | AK38: 91dbe8c0-e4cf-4058-a133-1ad625dc4ab2
A39: 373 | B39: 44603 | C39: =B39 -> 44603 | D39: Esri_Anonymous | E39: YECKASTORO JANUWISESA | F39: =E39 -> YECKASTORO JANUWISESA | G39: Proyek Peningkatan Jalan Sp. Siligita - Kempinski | I39: 0 | J39: 0 | K39: 0 | L39: 0 | M39: 0 | N39: 0 | O39: 0 | P39: 0 | Q39: 0 | R39: 0 | S39: 0 | T39: 0 | U39: 0 | V39: 0 | W39: 0 | X39: 0 | Y39: 0 | AA39: https://drive.google.com/file/d/1cRh0mkRmYQapfKQc5MJNXwwddD5qArPv/view?usp=share_link | AB39: https://drive.google.com/file/d/1c7FMSLa45dM05wRH_D1oEtUcV1F66J80/view?usp=share_link; https://drive.google.com/file/d/1O4I1zuyJeyjr40DshCJOerpZy95cC5f6/view?usp=share_link; https://drive.google.com/file/d/1JLTZnVinxoGH9GaDIaGbI0uU4I-Dfb1j/view?usp=share | AE39: =[1]!OfficeForms.Table[[#This Row],[Waktu selesai]] -> #REF! | AG39: =VLOOKUP(OfficeForms.Table[[#This Row],[Nama Proyek]],'Nama Proyek'!$D$2:$G$29,4,0) -> #N/A | AK39: 616a9607-fda0-408a-8bf0-c14df13084a4
A40: 698 | B40: 44628 | C40: =B40 -> 44628 | D40: Esri_Anonymous | E40: Nizar Zulkarnain | F40: =E40 -> Nizar Zulkarnain | G40: Jalan Tol Cimanggis Cibitung Seksi 2 | H40: 44773 | I40: 70.426 | J40: 71.455 | K40: 58.12 | L40: 55.31 | M40: 80.94 | N40: 77.67 | O40: 44.5 | P40: 58 | Q40: 53.55 | R40: 47.27 | S40: 81.89 | T40: 79.88 | U40: 27.81 | V40: 10.74 | W40: 0 | X40: 98.36 | Y40: 4.1 | AF40: PLN : tiang dan pln yg masih berada dilokasi menggangu jalannya progress pekerjaan PDAM : pipa PDAM yang belum terkoneksi di lahan Bea Cukai mengakibatkan pipa eksisting di lokasi frontage belum bisa dibongkar dan berdampak pek timbunan, aggregate A, di | AG40: =VLOOKUP(OfficeForms.Table[[#This Row],[Nama Proyek]],'Nama Proyek'!$D$2:$G$29,4,0) -> -6.35008011,107.02324233 | AK40: 51346516-6302-4696-bea3-35570b1cd623
...

Sheet Progress Test
A1: Nama Proyek | B1: Periode | C1: Rencana | D1: Realisasi
A2: Fly Over Simpang Sekip - Palembang (JOI 65%) | C2: 0 | D2: 0
A3: Fly Over Simpang Sekip - Palembang (JOI 65%) | C3: 0 | D3: 0
A4: Fly Over Simpang Sekip - Palembang (JOI 65%) | C4: 0 | D4: 0
A5: Fly Over Simpang Sekip - Palembang (JOI 65%) | C5: 0 | D5: 0
A6: Fly Over Simpang Sekip - Palembang (JOI 65%) | C6: 0 | D6: 0
A7: Fly Over Simpang Sekip - Palembang (JOI 65%) | C7: 0 | D7: 0
A8: Fly Over Simpang Sekip - Palembang (JOI 65%) | C8: 0 | D8: 0
A9: Fly Over Simpang Sekip - Palembang (JOI 65%) | C9: 0 | D9: 0
A10: Fly Over Simpang Sekip - Palembang (JOI 65%) | C10: 0 | D10: 0
A11: Fly Over Simpang Sekip - Palembang (JOI 65%) | C11: 0 | D11: 0
A12: Fly Over Simpang Sekip - Palembang (JOI 65%) | C12: 0 | D12: 0
A13: Fly Over Simpang Sekip - Palembang (JOI 65%) | C13: 0 | D13: 0
... A16: Fly Over Simpang Sekip - Palembang (JOI 65%) | C16: 0 | D16: 0
A17: Jalan Akses Bandara VVIP IKN (JOI 35%) | B17: 45657 | C17: 91.486 | D17: 91.365
A18: Jalan Baru Kretek Girijati (JOI Leader 52.5%) | B18: 45651 | C18: 70.961 | D18: 57.712
A19: Jalan Baru Kretek Girijati (JOI Leader 52.5%) | B19: 45682 | C19: 74.049 | D19: 60.862
A20: Jalan Baru Kretek Girijati (JOI Leader 52.5%) | B20: 45713 | C20: 76.06 | D20: 63.319
A21: Jalan Baru Kretek Girijati (JOI Leader 52.5%) | B21: 45772 | C21: 82.018 | D21: 71.509
A22: Jalan Baru Kretek Girijati (JOI Leader 52.5%) | B22: 45802 | C22: 84.648 | D22: 77.971
A23: Jalan Baru Kretek Girijati (JOI Leader 52.5%) | B23: 45863 | C23: 91.538 | D23: 91.448
A24: Jalan Baru Kretek Girijati (JOI Leader 52.5%) | B24: 45894 | C24: 94.02 | D24: 89.63
A25: Jalan Baru Kretek Girijati (JOI Leader 52.5%) | B25: 45925 | C25: 95.486 | D25: 91.969
A26: Jalan Baru Kretek Girijati (JOI Leader 52.5%) | C26: 0 | D26: 0
A27: Jalan Baru Kretek Girijati (JOI Leader 52.5%) | C27: 0 | D27: 0
A28: Jalan Baru Kretek Girijati (JOI Leader 52.5%) | C28: 0 | D28: 0
A29: Jalan Baru Kretek Girijati (JOI Leader 52.5%) | C29: 0 | D29: 0
A30: Jalan Baru Kretek Girijati (JOI Leader 52.5%) | B30: 45956 | C30: 89.868 | D30: 80.591
A31: Jalan dan Jembatan Bts. Blitar Lot 6B | B31: 44833 | C31: 31.972 | D31: 19.758
A32: Jalan dan Jembatan Bts. Blitar Lot 6B | B32: 44862 | C32: 39.934 | D32: 32.395
A33: Jalan dan Jembatan Bts. Blitar Lot 6B | B33: 44887 | C33: 44.435 | D33: 41.701
A34: Jalan dan Jembatan Bts. Blitar Lot 6B | B34: 44893 | C34: 46.983 | D34: 44.803
A35: Jalan dan Jembatan Bts. Blitar Lot 6B | B35: 44925 | C35: 47.71 | D35: 60.675
A36: Jalan dan Jembatan Bts. Blitar Lot 6B | B36: 44956 | C36: 48.587 | D36: 80.031
A37: Jalan dan Jembatan Bts. Blitar Lot 6B | B37: 44959 | C37: 48.587 | D37: 57.69
A38: Jalan dan Jembatan Bts. Blitar Lot 6B | B38: 45012 | C38: 52.673 | D38: 95.427
A39: Jalan Distrik (Feeder) IKN (JOI 50%) | B39: 45653 | C39: 100 | D39: 100
A40: Jalan Distrik (Feeder) IKN (JOI 50%) | B40: 44967 | C40: 5.626 | D40: 5.798
A41: Jalan Distrik (Feeder) IKN (JOI 50%) | C41: 0 | D41: 0
A42: Jalan Distrik (Feeder) IKN (JOI 50%) | C42: 0 | D42: 0
...

Sheet Nama Proyek
A1: No | B1: ID_Project | C1: BU | D1: Nama Proyek | E1: Lat | F1: Long | G1: Koord | H1: Status Project | I1: Panjang | J1: Cesium ION | K1: BimViewer
A2: 1 | B2: 1322032 | C2: Infrastructure II Division | D2: Jalan IKN Lingkar Sepaku Segmen 4 | E2: -0.95259625 | F2: 116.71704 | G2: -0.95259625,116.71704453 | H2: Finish
A3: 2 | B3: 1320027 | C3: Infrastructure II Division | D3: Jalan Sofi - Wayabula 1 | E3: 2.426249 | F3: 128.29766 | G3: 2.426249030,128.29766314 | H3: Finish
A4: 3 | B4: 1417059 | C4: Infrastructure II Division | D4: Jalan Tol Paspro Seksi 4 | E4: -7.8222517 | F4: 113.29968 | G4: -7.82225167,113.29968319 | H4: Finish
A5: 4 | B5: 1322039 | C5: Infrastructure II Division | D5: Rekonstruksi Jl. Kwatisore, Nabire, Papua (JOI 70%) | E5: -3.2507851 | F5: 134.87791 | G5: -3.25078511,134.87791156 | H5: Finish
A6: 5 | B6: 1316019 | C6: Infrastructure II Division | D6: Jalan Tol Bocimi Seksi 2 | E6: -6.8067546 | F6: 106.78537 | G6: -6.80675464,106.785366 | H6: Finish
A7: 6 | B7: 1321025 | C7: Infrastructure II Division | D7: Jalan Long Semamu - Long Bawan 2 (JOP 70%) | E7: 3.7604757 | F7: 115.89978 | G7: 3.76047575,115.89977678 | H7: Finish
A8: 7 | B8: 1317039 | C8: Infrastructure II Division | D8: Jalan Tol Cibitung - Cilincing Seksi 2 | E8: -6.1349105 | F8: 106.93676 | G8: -6.13491053,106.93675986 | H8: Finish
A9: 8 | B9: 1322008 | C9: Infrastructure II Division | D9: Fly Over Simpang Sekip - Palembang (JOI 65%) | E9: -2.952931 | F9: 104.75455 | G9: -2.95293103,104.75455094 | H9: Finish
A10: 9 | B10: 1320031 | C10: Infrastructure II Division | D10: Jalan SP. Blusuh – BTS. Kalteng JOP 62.5 | E10: 3.7627106 | F10: 115.88263 | G10: 3.76271056,115.88262689 | H10: Finish
A11: 10 | B11: 1321047 | C11: Infrastructure II Division | D11: Jalan Akses dan Kawasan Avasta | E11: -6.1296756 | F11: 107.07321 | G11: -6.12967558,107.07321308 | H11: On Hold
A12: 11 | B12: 1316022 | C12: Infrastructure II Division | D12: Jalan Tol Cimanggis Cibitung Seksi 2 | E12: -6.3500801 | F12: 107.02324 | G12: -6.35008011,107.02324233 | H12: Finish
A13: 12 | B13: 1323026 | C13: Infrastructure II Division | D13: Jalan Tol Bayunglencir - Tempino Seksi 1 (JOI 40%) | E13: -1.9839927 | F13: 103.71352 | G13: -1.98399270,103.7135193 | H13: Finish
... A17: 16 | B17: 1324004 | C17: Infrastructure II Division | D17: Jalan Tol IKN Seksi 3B-2 | E17: -1.1373191 | F17: 116.79021 | G17: -1.13731907,116.79020552 | H17: Finish
A18: 17 | B18: 1322033 | C18: Infrastructure II Division | D18: Jalan Tol IKN 5A Tempadung-Pulau Balang (JOI 50%) | E18: -1.1041534 | F18: 116.73424 | G18: -1.10415341,116.73424356 | H18: Finish | K18: "<iframe src='https://bimviewer.org/viewer/?urn=dXJuOmFkc2sub2JqZWN0czpvcy5vYmplY3Q6YXBzLWJpbS12aWV3ZXItYnVja2V0LWNxM3E0NnVrbWdrdHYxdTQ3aTByMHdsYXo5anQ2amF6cHZxeWF5MnVyZXlhNjN1Ni9TT1AlMjAyKzI0MC5ydnQ' style='position: fixed; width:100%; height:100%'></iframe>"
A19: 18 | B19: 1322024 | C19: Infrastructure II Division | D19: Rekonstruksi Jembatan Palu 4 | E19: -0.88562397 | F19: 119.85928 | G19: -0.88562397,119.85928375 | H19: Finish
A20: 19 | B20: 1323023 | C20: Infrastructure II Division | D20: Jalan Distrik (Feeder) IKN (JOI 50%) | E20: -0.9684943 | F20: 116.70188 | G20: -0.96849430,116.70188410 | H20: Finish
A21: 20 | B21: 1323043 | C21: Infrastructure II Division | D21: Pematangan Lahan KIT Batang Klaster 1 Fase 2 Tahap 1 (JOI 40%) | E21: -6.9272374 | F21: 109.95183 | G21: -6.92723742,109.95182730 | H21: Finish
A22: 21 | B22: 1324008 | C22: Infrastructure II Division | D22: Jalan Akses Bandara VVIP IKN (JOI 35%) | E22: -1.1520556 | F22: 116.69317 | G22: -1.15205556,116.69316667 | H22: Finish
A23: 22 | B23: 1319010 | C23: Infrastructure II Division | D23: Jalan Tol Becakayu 2A Ujung | E23: -6.2501111 | F23: 106.99919 | G23: -6.4209386,107.1876008 | H23: Finish
A24: 23 | B24: 1323007 | C24: Infrastructure II Division | D24: Patimban Port Development Paket 5 (JOI member 16%) | E24: -6.2319126 | F24: 107.90813 | G24: -6.23191260,107.90813480 | H24: On Going
A25: 24 | B25: 1323045 | C25: Infrastructure II Division | D25: Jalan Seksi 6C-1 KIPP IKN (JOI 32.50%) | E25: -0.99046214 | F25: 116.69025 | G25: -0.99046214,116.69024762 | H25: Finish
A26: 25 | B26: 1323019 | C26: Infrastructure II Division | D26: Underpass Deltamas SS Sukabungah | E26: -6.4209386 | F26: 107.1876 | G26: -6.42093860,107.18760070 | H26: Finish
A27: 26 | B27: 1323020 | C27: Infrastructure II Division | D27: Jalan Tol Probolinggo Bayuwangi Paket 3 (JOI member 25%) | E27: -7.7264769 | F27: 113.63515 | G27: -7.72647690,113.63515320 | H27: On Going | J27: https://ion.cesium.com/stories/viewer/?id=6d6812ab-f9f1-4950-84d4-65f4f479c8a7
A28: 27 | B28: 1323025 | C28: Infrastructure II Division | D28: Jalan Baru Kretek Girijati (JOI Leader 52.5%) | E28: -8.010033 | F28: 110.33313 | G28: -8.01003300,110.33312900 | H28: On Going
A29: 28 | B29: 1323039 | C29: Infrastructure II Division | D29: Jalan Lot 2 Buluwalang-Sidomulyo-Tambakrejo (JOI 40%) | E29: -8.309619 | F29: 112.11101 | G29: -8.30961900,112.11101000 | H29: On Going
A30: 29 | B30: 1323042 | C30: Infrastructure II Division | D30: Jalan Tol Bocimi Seksi 3A | E30: -6.881205 | F30: 106.78938 | G30: -6.88120502,106.78938277 | H30: On Going | K30: "<iframe src='https://bimviewer.org/viewer/?urn=dXJuOmFkc2sub2JqZWN0czpvcy5vYmplY3Q6YXBzLWJpbS12aWV3ZXItYnVja2V0LWNxM3E0NnVrbWdrdHYxdTQ3aTByMHdsYXo5anQ2amF6cHZxeWF5MnVyZXlhNjN1Ni9KRU1CQVRBTiUyMDE2MCUyMGtvb3JkaW5hdCUyMGJhcnUlMjAyJTIwLSUyMENvcHkucnZ0' style='position: fixed; width:100%; height:100%'></iframe>"
A31: 30 | B31: 1324001 | C31: Infrastructure II Division | D31: Jalan Tol Akses Patimban Paket 2 (JOI 60%) | E31: -6.335333 | F31: 107.77576 | G31: -6.33533300,107.77576100 | H31: On Going
A32: 31 | B32: 1322002 | C32: Infrastructure II Division | D32: Proyek Peningkatan Jalan Sp. Siligita - Kempinski | E32: -8.8056484 | F32: 115.22343 | G32: -6.42093860,107.18760090 | H32: Finish
A33: 31 | B33: 1325012 | C33: Infrastructure II Division | D33: Peningkatan Jalan Paket D KIPP 1C | E33: -1.0121252 | F33: 116.66359 | G33: =CONCATENATE(Table3[[#This Row],[Lat]],",",Table3[[#This Row],[Long]]) -> -1.0121252,116.6635897 | H33: On Going
A34: 32 | B34: 1324010 | C34: Infrastructure II Division | D34: Jalan Tol Bocimi Seksi 3B | E34: -6.881205 | F34: 106.78938 | G34: =CONCATENATE(Table3[[#This Row],[Lat]],",",Table3[[#This Row],[Long]]) -> -6.8812050213,106.7893827682 | H34: On Going
A35: 33 | B35: 1326001 | C35: Infrastructure II Division | D35: Jembatan Kalimantan-Pulau Laut(JOI 20%) | E35: -3.471378 | F35: 116.02859 | G35: =CONCATENATE(Table3[[#This Row],[Lat]],",",Table3[[#This Row],[Long]]) -> -3.471378,116.028586 | H35: On Going
A36: 34 | C36: Infrastructure II Division | D36: Perbaikan Geometrik Jalan Mengwitani Singaraja | E36: -8.199858 | F36: 115.1423 | G36: =CONCATENATE(Table3[[#This Row],[Lat]],",",Table3[[#This Row],[Long]]) -> -8.199858,115.1423 | H36: On Going
A37: 35 | C37: Infrastructure II Division | D37: Pembangunan Jalan Kompleks Kawasan Yudikatif IKN | E37: -0.964223 | F37: 116.69809 | G37: =CONCATENATE(Table3[[#This Row],[Lat]],",",Table3[[#This Row],[Long]]) -> -0.964223,116.698095 | H37: On Going

Sheet Sheet3
A1: Jalan Tol Japek 2 Selatan Paket 3 Induk | B1: -6.42873464,107.19897003 | C1: On Going | D1: -6.4287346 | E1: 107.19897
A2: Jalan Tol Bocimi Seksi 2 | B2: -6.80675464,106.785366 | C2: Finish | D2: -6.8067546 | E2: 106.78537
A3: Jalan Jalan Tol Cimanggis Cibitung Seksi 2 | B3: -6.35008011,107.02324233 | C3: Finish | D3: -6.3500801 | E3: 107.02324
A4: Jalan Tol Cibitung - Cilincing Seksi 2 | B4: -6.13491053,106.93675986 | C4: Finish | D4: -6.1349105 | E4: 106.93676
A5: Jalan Tol Paspro Seksi 4 | B5: -7.82225167,113.29968319 | C5: Finish | D5: -7.8222517 | E5: 113.29968
A6: Jalan Sofi - Wayabula 1 | B6: 2.42624903,128.29766314 | C6: Finish | D6: 2.426249 | E6: 128.29766
A7: Jalan SP. Blusuh – BTS. Kalteng JOP 62.5 | B7: 3.76271056,115.88262689 | C7: Finish | D7: 3.7627106 | E7: 115.88263
A8: Jalan dan Jembatan Batas Kab. Blitar Lot 6B | B8: -8.29394978,112.00545006 | C8: Finish | D8: -8.2939498 | E8: 112.00545
A9: Jalan Akses dan Kawasan Avasta | B9: -6.12967558,107.07321308 | C9: On Hold | D9: -6.1296756 | E9: 107.07321
A10: Fly Over Simpang Sekip - Palembang JOI 65% | B10: -2.95293103,104.75455094 | C10: Finish | D10: -2.952931 | E10: 104.75455
A11: Rekonstruksi Jembatan Palu 4 | B11: -0.88562397,119.85928375 | C11: Finish | D11: -0.88562397 | E11: 119.85928
A12: Jalan Tol IKN Tempadung-Pulau Balang (JOI 50%) | B12: -1.104153412,116.73424356 | C12: Finish | D12: -1.1041534 | E12: 116.73424
... A28: Peningkatan Jalan Paket D KIPP 1C | B28: -1.01212520,116.66358970 | C28: On Going | D28: -1.0121252 | E28: 116.66359

Sheet Sheet4
A1: item
A2: Nama Proyek
A3: Pengguna Jasa
A4: Lokasi Proyek
A5: Tanggal SPMK
A6: Jangka Waktu Pelaksanaan
A7: Masa Pemeliharaan
A8: Jenis Kontrak
A9: Cara Pembayaran
A10: Nilai Kontrak
A11: Retensi
A12: Kontraktor Pelaksana
A13: Lingkup Pekerjaan

Sheet Informasi Umum 2
A1: Nama Proyek | B1: Nama Proyek | C1: Pengguna Jasa | D1: Lokasi Proyek | E1: Tanggal SPMK | F1: Jangka Waktu Pelaksanaan | G1: Masa Pemeliharaan | H1: Jenis Kontrak | I1: Cara Pembayaran | J1: Nilai Kontrak | K1: Retensi | L1: Kontraktor Pelaksana | M1: Lingkup Pekerjaan
A2: =Table2[[#This Row],[Nama Proyek]] -> Jalan Tol Bocimi Seksi 3 | B2: Pembangunan Jalan Tol Ciawi - Sukabumi Seksi 3 STA 26+500 sd 40+200, 13,7 km | C2: PT Trans Jabar Tol | D2: Kab Sukabumi, Prov Jawa Barat | E2: 45257 | F2: 731 Hari Kalender | G2: 1095 Hari Kalender | H2: Fixed Unit Price | I2: Sertifikat Bulanan | J2: Rp 1876743479356 (NK + PPn 11%) | K2: 0.05 | L2: PT Waskita Karya (Persero) | M2: 0
A3: Jalan Lot 2 Buluwalang-Sidomulyo-Tambakrejo (JOI 40%) | B3: Pembangunan Jalan Lintas Selatan Lot 2:Bululawang - Sidomulyo - Tambakrejo | C3: Satker Pelaksanaan Jalan Nasional Wilayah II Prov. Jawa Timur Pejabat Pembuat Komitmen 2.7 Provinsi Jawa Timur | D3: Kab. Blitar, Prov. Jawa Timur | E3: 45226 | F3: 1020 Hari Kalender dari SPMK | G3: 365 Hari Kalender | H3: Unit Price | I3: Interim Payment Certificate (Monthly Payment) | J3: 316419029407 | K3: 0 | L3: PP - WASKITA - SMU | M3: Panjang 12.775km; Box Culvert 23 unit; Jembatan (30m) 3 unit
A4: Jalan Distrik (Feeder) IKN (JOI 50%) | B4: Pembangunan Jalan di dalam KIPP: Paket Pembangunan Jalan Feeder (Distrik) di Kawasan IKN | C4: Kementerian PUPR Direktorat Jendral Bina Marga | D4: Kabupaten Penajam Paser Utara, Prov. Kalimantan Timur | E4: 45112 | F4: 11 Juli 2023 sd 04 Agustus 2024 (390 hari kalender) | G4: 365 Hari Kalender | H4: Unit Price | I4: Sertifikat Bulanan | J4: 1160870287394 | K4: 0 | L4: Waskita - Nindya - Permata KSO | M4: Pembangunan dan pembukaan jalan baru di KIPP 10.30km; 1 jembatan; Multi Utility Tunnel (MUT) 8.37km; Box Culvert 26 buah
A5: Jalan Baru Kretek Girijati (JOI Leader 52.5%) | B5: Jalan Kretek - Girijati (JOI 52.5%) | C5: Kementerian PUPR Direktorat Jendral Bina Marga PPK DI Yogyakarta | D5: Prov. DI Yogyakarta | E5: 45140 | F5: 02 Agustus 2023 sd 22 Juli 2025 (720 hari kalender) | G5: 365 Hari Kalender | H5: Unit Price | I5: Sertifikat Bulanan | J5: 241031298951 | K5: 0 | L5: Waskita - PP | M5: 0
A6: Jalan Seksi 6C-1 KIPP IKN (JOI 32.50%) | B6: Jalan IKN Seksi 6C-1 (JOI 32.5%) | C6: Kementerian PUPR Direktorat Jendral Bina Marga Balai Besar Pelaksanaan | D6: Provinsi Kalimantan Timur | E6: 45267 | F6: 7 Desember 2023 sd 30 Desember 2024 (389 Hari Kalender) | G6: 365 Hari Kalender | H6: Unit Price | I6: Monthly Payment | J6: 1493278263794 | K6: 0 | L6: PP - WASKITA - Yasa Patria Perkasa | M6: 0
A7: Pematangan Lahan KIT Batang Klaster 1 Fase 2 Tahap 1 (JOI 40%) | B7: Pematangan Lahan KITB JOI 40% | C7: PPK Kasawan Industri Batang I, BBPJN Jawa Tengah - DIY, PUPR Bina Marga | D7: Kabupaten Batang, Prov. Jawa Tengah | E7: 45239 | F7: 9 November 2023 sd 3 September 2024 (300 hari Kalender) | G7: 180 hari kalender | H7: Unit Price | I7: Monthly Payment | J7: 463336549270 | K7: 0 | L7: Nindya Karya - Waskita Karya - Bina Nusa Lestari | M7: 0
A8: Jalan Tol Probolinggo Bayuwangi Paket 3 (JOI member 25%) | B8: Probolinggo - Banyuwangi Paket 3 (JOP 25%) | C8: PT. Jasamarga Probolinggo - Banyuwangi | D8: Provinsi Jawa Timur | E8: 44978 | F8: 12 Juni 2023 sd 12 Desember 2024 (549 hari Kalender) | G8: 13 Desember 2024 sd 12 Desember 2026 (1095 Hari Kalender) | H8: Gabungan Lumpsum dan Unit Price | I8: Monthly Payment | J8: 3987286153268 | L8: PP - Waskita Karya - Wijaya Karya | M8: 0
A9: Underpass Deltamas SS Sukabungah | B9: Akses Jalan Tol Japek Selatan (Deltamas) | C9: PT. Puradelta Lestari | D9: Kab. Bekasi, Prov. Jawa Barat | E9: 45097 | F9: 26 Juni 2023 sd 23 Desember 2023 (180 hari kalender) | G9: 1095 Hari Kalender | H9: Unit Price | I9: Sertifikat Bulanan | J9: 100900000000 | K9: 0 | L9: Waskita Karya | M9: STA 4+400 - 5+000 (600m)
A10: Fly Over Simpang Sekip - Palembang (JOI 65%) | B10: Pembangunan FO Sekip Ujung | C10: PPK 3.6 Provinsi Sumatera Selatan | D10: Palembang, Prov. Sumatera Selatan | F10: 630 hari kalender | G10: 0 | H10: 0 | I10: Sertifikat Bulanan | J10: 152943426000 | K10: 0 | L10: Waskita - Kencana KSO | M10: STA 0+000 - 0+660 (660m)
A11: Patimban Port Development Paket 5 (JOI member 16%) | B11: Patimban Port Development Project Package 5: Car Terminal Construction | C11: Kementerian Perhubungan - Dirjen Perhubungan Laut | D11: Kab. Subang, Provinsi Jawa Barat | E11: 45016 | F11: 730 hari kalender dari tanggal SPMK | G11: 0 | H11: Unit Price | I11: Monthly Payment | J11: 2383566664079 | K11: 0 | L11: TOA - Waskita - Wakachiku - HK - Abipraya | M11: 0
A12: Jalan Akses Bandara VVIP IKN (JOI 35%) | B12: Jalan Akses Bandara VVIP IKN (JOI 35%) | C12: Kementerian PUPR Direktorat Jenderal Bina Marga Balai | D12: Provinsi Kalimantan Timur | E12: 45306 | F12: 16 Januari s.d. 31 Desember 2024 (350 hari) | G12: 365 hari kalender | H12: Unit Price | I12: Monthly Payment | J12: 853785920150 | K12: 0 | L12: Nindya Karya - Waskita Karya - Naviri Multi Konstruksi - Panca Karya Sentosa | M12: Jalan Akses 1.74km; Interchange 6 ramp; Jalan Provinsi 850m
A13: Jalan Tol Bayunglencir - Tempino Seksi 1 (JOI 40%) | B13: Jalan Tol Bayunglencir - Tempino Seksi 1 (JOI 40%) | C13: PPK 1.1 Satuan Kerja PJN Wilayah Provinsi Sumatera Utara | D13: Provinsi Jambi | E13: 45063 | F13: 27 Mei 2023 s.d 30 Juni 2024 (520 hari) | G13: 365 hari kalender | H13: Gabungan lumpsum dan unit price | I13: Monthly Payment | J13: 1455374902280 | K13: 0 | L13: Adhi Karya - Waskita Karya - Jaya Konstruksi | M13: Mainroan 7.625km; Akses tol 2.90km
A14: Jalan Tol IKN Seksi 3B-2 | B14: Tol IKN Seksi 3B-2 JOI 20% | C14: Kementerian PUPR Direktorat Jenderal Bina Marga Balai Pelaksana Jalan Nasional Kalimantan Timur | D14: Balikpapan, Prov. Kalimantan Timur | E14: 45281 | F14: 21 Desember 2023 - 12 Juni 2025 (539 hari kalender) | G14: 365 hari kalender | H14: Unit Price | I14: Monthly Payment | J14: 2399426628007 | K14: 0 | L14: Wijaya Karya - Waskita Karya - Jaya Konstruksi - PP | M14: Elevated pile slab 1.26km; interchange KKT Kariangau 1 lokasi; Jembatan satwa 2 lokasi
A15: Jalan Tol Akses Patimban Paket 2 (JOI 60%) | B15: Pembangunan Jalan Tol Akses Patimban Paket 2 | C15: Kementerian PUPR Dirjen Bina Marga | D15: Kab. Subang, Prov. Jawa Barat | F15: 3 Januari 2024 - 02 Desember 2025 (700 hari Kalender) | G15: 365 hari kalender | H15: 0 | I15: Sertifikat Bulanan | J15: 8.7353754e+11 | K15: 0 | L15: Waskita - Abipraya | M15: Civil works main road 6.2KM (STA 21+800 - 28+000), 5 bridge, 1 overpass
A16: Rekonstruksi Jl. Kwatisore, Nabire, Papua (JOI 70%) | B16: Pekerjaan Rekonstruksi Jalan Kwatisore-Kaamp. Muri (Bts Provinsi Papua Barat) I | C16: Dirjen Binamarga Pelaksanaan Jalan Nasional Wilayah VII Provinsi Papua (Nabire) | D16: Kabupaten Nabire, Provinsi Papua | F16: 510 hari kalender | G16: 365 hari kalender | H16: Unit Price | I16: Monthly Payment | J16: 1.3297678e+11 | K16: 0 | L16: Waskita - Karya Mandiri Permai KSO | M16: Pembangunan Jalan sampai perkerasan panjang 16.45 km (KM 113+420 sd 121+300 dan KM 129+700 sd 138+200)
A17: Jalan IKN Lingkar Sepaku Segmen 4 (JOI 70%) | B17: Jalan IKN Sepaku Segmen 4 JOI 70% | C17: Kementerian PUPR – BBPJN Kalimantan Timur – Satuan Kerja Pelaksanaan Pembangunan IKN 2 | D17: Penajam Paser Utara, Kalimantan Timur | E17: 44802 | F17: 19/09/2022 – 04/05/2024 (594 hari) | G17: 182 hari | H17: Fix Unit Price | I17: Monthly Payment | J17: 1.7990525e+11 | K17: 0 | L17: 0 | M17: 0
A18: Jalan Tol IKN 5A Tempadung-Pulau Balang (JOI 50%) | B18: Jalan Tol IKN Segmen Sp. Tempadung - Jemb. Pulau Balang (JOI 50%) | C18: Kementerian PUPR | D18: Tempadung-Pulau Balang, Kalimantan Timur | E18: 44813 | F18: 730 hari | G18: 0 | I18: Monthly Payment | J18: 2.1982553e+12 | L18: Waskita- Nindya - Modern KSO | M18: Jalan 4.755km; elevated pile slab 1.380 (7 lokasi); jjembatan 2 buah; Box Culvert 12 buah
A19: Rekonstruksi Jembatan Palu 4 | B19: Rekonstruksi Jembatan Palu 4 | C19: Tokyu Construction Co., Ltd. | D19: Palu, Sulawesi Tengah | E19: 44734 | F19: 730 hari (s.d. 30 Juni 2024) | G19: 365 hari kalender | H19: Lumpsum | I19: Monthly Payment with Minimum Progress | J19: 1787000000 | K19: 0 | L19: 0 | M19: Jembatan dan pendekat (380+250+410m).
A20: Jalan Tol Cibitung - Cilincing Seksi 2 | B20: Cimanggis - Cibitung Seksi 2 | C20: PT. Cimanggis Cibitung Tollways | D20: Bogor, Bekasi,Prov. Jawa Barat | E20: 42547 | F20: sd Mei 2024 (Cikeas - Cibitung) | G20: 1095 hari kalender | H20: Fixed Unit Price | I20: Termin | J20: 3.8280372e+12 | K20: 0 | L20: PT. Waskita Karya | M20: Jalan Tol
A21: Jalan Tol Serang - Panimbang Seksi III Fase 2 Paket 3 | B21: Proyek Jalan Tol Serang - Penimbang Seksi 3 JOI 27.5% | C21: Satker JBH Serang - Panimbang, Balai Prov Banten, Kementerian PUPR | D21: Kab. Pandeglang, Prov. Banten | E21: 45268 | F21: 390 hari kalender setelah SPMK terbit | G21: 365 hari kalender | H21: Kontrak Harga Satuan | I21: Sertifikat Bulanan | J21: 1915188111950 | K21: 0 | L21: PP - Adhi Karya - Waskita Karya - Modern | M21: Jalan Tol
A22: Proyek Peningkatan Jalan Sp. Siligita - Kempinski | B22: Peningkatan Jalan Sp. Siligita-Kempinski, Showcase Mangrove | C22: Kementerian PUPR, Ditjen Binamarga, Balai Besar Pelaksanaan Jalan Nasional Jawa Timur & Bali | D22: Nusa Dua, Prov. Bali | E22: 44673 | F22: Februari 2022 sd September 2022 | G22: 0 | H22: Fix Unit Price | I22: Monthly Payment | J22: 1.2000283e+11 | K22: 0 | L22: PT. Waskita Karya | M22: 5.225 KM (Sp Siligita - Kempinski) dan 1.5km (Showcase Mangrove)

Sheet Informasi Umum
A1: No | B1: Item | C1: Deskripsi | D1: Nama Proyek | E1: ID_Project
A2: 1 | B2: Nama Proyek | C2: Pembangunan Jalan Tol Ciawi - Sukabumi Seksi 3 STA 26+500 sd 40+200, 13,7 km | D2: Jalan Tol Bocimi Seksi 3 | E2: 1323042
A3: 2 | B3: Pengguna Jasa | C3: PT Trans Jabar Tol | D3: Jalan Tol Bocimi Seksi 3 | E3: 1323042
A4: 3 | B4: Lokasi Proyek | C4: Kab Sukabumi, Prov Jawa Barat | D4: Jalan Tol Bocimi Seksi 3 | E4: 1323042
A5: 4 | B5: Tanggal SPMK | C5: 27 November 2023 | D5: Jalan Tol Bocimi Seksi 3 | E5: 1323042
A6: 5 | B6: Jangka Waktu Pelaksanaan | C6: 731 Hari Kalender | D6: Jalan Tol Bocimi Seksi 3 | E6: 1323042
A7: 6 | B7: Masa Pemeliharaan | C7: 1095 Hari Kalender | D7: Jalan Tol Bocimi Seksi 3 | E7: 1323042
A8: 7 | B8: Jenis Kontrak | C8: Fixed Unit Price | D8: Jalan Tol Bocimi Seksi 3 | E8: 1323042
A9: 8 | B9: Cara Pembayaran | C9: Sertifikat Bulanan | D9: Jalan Tol Bocimi Seksi 3 | E9: 1323042
A10: 9 | B10: Nilai Kontrak | C10: Rp 1.876.743.479.356 (NK + PPn 11%) | D10: Jalan Tol Bocimi Seksi 3 | E10: 1323042
A11: 10 | B11: Retensi | C11: 5% | D11: Jalan Tol Bocimi Seksi 3 | E11: 1323042
A12: 11 | B12: Kontraktor Pelaksana | C12: PT Waskita Karya (Persero) | D12: Jalan Tol Bocimi Seksi 3 | E12: 1323042
A13: 12 | B13: Lingkup Pekerjaan | D13: Jalan Tol Bocimi Seksi 3 | E13: 1323042
A14: 1 | B14: Nama Proyek | C14: Pembangunan Jalan Lintas Selatan Lot 2:Bululawang - Sidomulyo - Tambakrejo | D14: Jalan Lot 2 Buluwalang-Sidomulyo-Tambakrejo (JOI 40%) | E14: 1323039
A15: 2 | B15: Pengguna Jasa | C15: Satker Pelaksanaan Jalan Nasional Wilayah II Prov. Jawa Timur Pejabat Pembuat Komitmen 2.7 Provinsi Jawa Timur | D15: Jalan Lot 2 Buluwalang-Sidomulyo-Tambakrejo (JOI 40%) | E15: 1323039
A16: 3 | B16: Lokasi Proyek | C16: Kab. Blitar, Prov. Jawa Timur | D16: Jalan Lot 2 Buluwalang-Sidomulyo-Tambakrejo (JOI 40%) | E16: 1323039
A17: 4 | B17: Tanggal SPMK | C17: 27 Oktober 2023 | D17: Jalan Lot 2 Buluwalang-Sidomulyo-Tambakrejo (JOI 40%) | E17: 1323039
A18: 5 | B18: Jangka Waktu Pelaksanaan | C18: 1020 Hari Kalender dari SPMK | D18: Jalan Lot 2 Buluwalang-Sidomulyo-Tambakrejo (JOI 40%) | E18: 1323039
A19: 6 | B19: Masa Pemeliharaan | C19: 365 Hari Kalender | D19: Jalan Lot 2 Buluwalang-Sidomulyo-Tambakrejo (JOI 40%) | E19: 1323039
A20: 7 | B20: Jenis Kontrak | C20: Unit Price | D20: Jalan Lot 2 Buluwalang-Sidomulyo-Tambakrejo (JOI 40%) | E20: 1323039
A21: 8 | B21: Cara Pembayaran | C21: Interim Payment Certificate (Monthly Payment) | D21: Jalan Lot 2 Buluwalang-Sidomulyo-Tambakrejo (JOI 40%) | E21: 1323039
A22: 9 | B22: Nilai Kontrak | C22: Rp 316.419.029.407 | D22: Jalan Lot 2 Buluwalang-Sidomulyo-Tambakrejo (JOI 40%) | E22: 1323039
A23: 10 | B23: Retensi | D23: Jalan Lot 2 Buluwalang-Sidomulyo-Tambakrejo (JOI 40%) | E23: 1323039
A24: 11 | B24: Kontraktor Pelaksana | C24: PP - WASKITA - SMU | D24: Jalan Lot 2 Buluwalang-Sidomulyo-Tambakrejo (JOI 40%) | E24: 1323039
A25: 12 | B25: Lingkup Pekerjaan | C25: Panjang 12.775km; Box Culvert 23 unit; Jembatan (30m) 3 unit | D25: Jalan Lot 2 Buluwalang-Sidomulyo-Tambakrejo (JOI 40%) | E25: 1323039
A26: 1 | B26: Nama Proyek | C26: Pembangunan Jalan di dalam KIPP: Paket Pembangunan Jalan Feeder (Distrik) di Kawasan IKN | D26: Jalan Distrik (Feeder) IKN (JOI 50%) | E26: 1323025
A27: 2 | B27: Pengguna Jasa | C27: Kementerian PUPR Direktorat Jendral Bina Marga | D27: Jalan Distrik (Feeder) IKN (JOI 50%) | E27: 1323025
A28: 3 | B28: Lokasi Proyek | C28: Kabupaten Penajam Paser Utara, Prov. Kalimantan Timur | D28: Jalan Distrik (Feeder) IKN (JOI 50%) | E28: 1323025
A29: 4 | B29: Tanggal SPMK | C29: 5 Juli 2023 | D29: Jalan Distrik (Feeder) IKN (JOI 50%) | E29: 1323025
A30: 5 | B30: Jangka Waktu Pelaksanaan | C30: 11 Juli 2023 sd 04 Agustus 2024 (390 hari kalender) | D30: Jalan Distrik (Feeder) IKN (JOI 50%) | E30: 1323025
A31: 6 | B31: Masa Pemeliharaan | C31: 365 Hari Kalender | D31: Jalan Distrik (Feeder) IKN (JOI 50%) | E31: 1323025
A32: 7 | B32: Jenis Kontrak | C32: Unit Price | D32: Jalan Distrik (Feeder) IKN (JOI 50%) | E32: 1323025
A33: 8 | B33: Cara Pembayaran | C33: Sertifikat Bulanan | D33: Jalan Distrik (Feeder) IKN (JOI 50%) | E33: 1323025
A34: 9 | B34: Nilai Kontrak | C34: Rp 1.160.870.287.394 | D34: Jalan Distrik (Feeder) IKN (JOI 50%) | E34: 1323025
A35: 10 | B35: Retensi | D35: Jalan Distrik (Feeder) IKN (JOI 50%) | E35: 1323025
A36: 11 | B36: Kontraktor Pelaksana | C36: Waskita - Nindya - Permata KSO | D36: Jalan Distrik (Feeder) IKN (JOI 50%) | E36: 1323025
A37: 12 | B37: Lingkup Pekerjaan | C37: Pembangunan dan pembukaan jalan baru di KIPP 10.30km; 1 jembatan; Multi Utility Tunnel (MUT) 8.37km; Box Culvert 26 buah | D37: Jalan Distrik (Feeder) IKN (JOI 50%) | E37: 1323025
A38: 1 | B38: Nama Proyek | C38: Jalan Kretek - Girijati (JOI 52.5%) | D38: Jalan Baru Kretek Girijati (JOI Leader 52.5%) | E38: 1323026
A39: 2 | B39: Pengguna Jasa | C39: Kementerian PUPR Direktorat Jendral Bina Marga PPK DI Yogyakarta | D39: Jalan Baru Kretek Girijati (JOI Leader 52.5%) | E39: 1323026
A40: 3 | B40: Lokasi Proyek | C40: Prov. DI Yogyakarta | D40: Jalan Baru Kretek Girijati (JOI Leader 52.5%) | E40: 1323026
...
